<mujoco model="X5_umi_dual">
  <compiler angle="radian" autolimits="true"/>

  <asset>
    <mesh name="base_link" content_type="model/stl" file="./meshes/X5/base_link.STL"/>
    <mesh name="link1" content_type="model/stl" file="./meshes/X5/link1.STL"/>
    <mesh name="link2" content_type="model/stl" file="./meshes/X5/link2.STL"/>
    <mesh name="link3" content_type="model/stl" file="./meshes/X5/link3.STL"/>
    <mesh name="link4" content_type="model/stl" file="./meshes/X5/link4.STL"/>
    <mesh name="link5" content_type="model/stl" file="./meshes/X5/link5.STL"/>
    <mesh name="arx_gopro_finray_gripper" content_type="model/stl" file="./meshes/arx_gopro_finray_gripper.stl"/>
  </asset>

  <default>
    <default class="joint1">
      <joint axis="0 0 1" range="-3.14158 3.14158" damping="2.0" actuatorfrcrange="-100 100"/>
      <position ctrlrange="-3.14158 3.14158" kp="80"/>
    </default>
    <default class="joint2">
      <joint axis="0 1 0" range="0 3.14" damping="5.0" actuatorfrcrange="-100 100"/>
      <position ctrlrange="0 3.14" kp="120"/>
    </default>
    <default class="joint3">
      <joint axis="0 1 0" range="0 3.14" damping="4.0" actuatorfrcrange="-30 30"/>
      <position ctrlrange="0 3.14" kp="80"/>
    </default>
    <default class="joint4">
      <joint axis="0 1 0" range="-1.5708 1.5708" damping="2.0" actuatorfrcrange="-30 30"/>
      <position ctrlrange="-1.5708 1.5708" kp="40"/>
    </default>
    <default class="joint5">
      <joint axis="0 0 1" range="-1.67 1.67" damping="1.5" actuatorfrcrange="-100 100"/>
      <position ctrlrange="-1.67 1.67" kp="40"/>
    </default>
    <default class="joint6">
      <joint axis="1 0 0" range="-1.57 1.57" damping="1.0" actuatorfrcrange="-30 30"/>
      <position ctrlrange="-1.57 1.57" kp="25"/>
    </default>
    <default class="finger">
      <joint type="slide" range="0 0.041" damping="20" actuatorfrcrange="-30 30"/>
      <position ctrlrange="0.002 0.037" kp="500" kv="40"/>
    </default>
  </default>

  <worldbody>
    <body name="left/base_link" pos="-0.22 -0.4 0" quat="0.70710678 0 0 0.70710678">
      <geom type="mesh" contype="0" conaffinity="0" group="1" density="0" rgba="0.75294 0.75294 0.75294 1" mesh="base_link"/>
      <geom type="mesh" rgba="0.75294 0.75294 0.75294 1" mesh="base_link"/>
      <body name="left/link1" pos="0 0 0.0603">
        <inertial pos="0.00571213 0.0002547 0.0175066" quat="0.680193 0.680193 -0.193229 0.193229" mass="0.064" diaginertia="8.61803e-05 6.38197e-05 3e-05"/>
        <joint name="left/joint1" pos="0 0 0" class="joint1"/>
        <geom type="mesh" contype="0" conaffinity="0" group="1" density="0" rgba="0.75294 0.75294 0.75294 1" mesh="link1"/>
        <geom type="mesh" rgba="0.75294 0.75294 0.75294 1" mesh="link1"/>
        <body name="left/link2" pos="0.02 0 0.0402">
          <inertial pos="-0.132257 0.00072373 4.274e-05" quat="0.00129315 0.707299 -0.000908747 0.706913" mass="1.165" diaginertia="0.0368349 0.0366996 0.000570269"/>
          <joint name="left/joint2" pos="0 0 0" class="joint2"/>
          <geom type="mesh" contype="0" conaffinity="0" group="1" density="0" rgba="0.75294 0.75294 0.75294 1" mesh="link2"/>
          <geom type="mesh" rgba="0.75294 0.75294 0.75294 1" mesh="link2"/>
          <body name="left/link3" pos="-0.264 0 0" quat="-3.67321e-06 -1 0 0">
            <inertial pos="0.190961 0.00069065 -0.0534217" quat="0.429937 0.563106 0.5511 0.440856" mass="0.546" diaginertia="0.0248663 0.0247163 0.000360764"/>
            <joint name="left/joint3" pos="0 0 0" class="joint3"/>
            <geom type="mesh" contype="0" conaffinity="0" group="1" density="0" rgba="0.75294 0.75294 0.75294 1" mesh="link3"/>
            <geom size="0.02 0.075" pos="0.15 0 -0.055" quat="0.707107 0 0.707107 0" type="cylinder" rgba="0.75294 0.75294 0.75294 1"/>
            <body name="left/link4" pos="0.245 0 -0.056">
              <inertial pos="0.0309232 0.0066107 -0.031385" quat="0.948284 -0.112586 -0.277756 0.10456" mass="0.080971" diaginertia="0.000231095 0.000214473 5.78516e-05"/>
              <joint name="left/joint4" pos="0 0 0" class="joint4"/>
              <geom type="mesh" contype="0" conaffinity="0" group="1" density="0" rgba="0.89804 0.91765 0.92941 1" mesh="link4"/>
              <geom size="0.025 0.025" pos="0.06575 -0.001 -0.02" type="cylinder" rgba="0.89804 0.91765 0.92941 1"/>
              <body name="left/link5" pos="0.06575 -0.001 -0.0825">
                <inertial pos="0.0040681 8.85e-06 0.0512068" quat="0.998879 0.000248436 0.0466541 0.00797966" mass="0.655" diaginertia="0.00256988 0.00255018 0.000249451"/>
                <joint name="left/joint5" pos="0 0 0" class="joint5"/>
                <geom type="mesh" contype="0" conaffinity="0" group="1" density="0" rgba="0.75294 0.75294 0.75294 1" mesh="link5"/>
                <geom size="0.02 0.0125" pos="0.055 0 0.083" quat="0.707107 0 0.707107 0" type="cylinder" rgba="0.75294 0.75294 0.75294 1"/>
                <body name="left/link6" pos="0.02845 0 0.0825" quat="-3.67321e-06 -1 0 0">
                  <inertial pos="0.0543717 -0.00733924 0.0188099" quat="0.391972 0.580147 0.313722 0.641378" mass="0.9021" diaginertia="0.00627428 0.00505738 0.00224351"/>
                  <joint name="left/joint6" pos="0 0 0" class="joint6"/>
                  <geom type="mesh" contype="0" conaffinity="0" group="1" density="0" rgba="0.89804 0.91765 0.92941 1" mesh="arx_gopro_finray_gripper"/>
                  <geom type="mesh" rgba="0.89804 0.91765 0.92941 1" mesh="arx_gopro_finray_gripper"/>
                  <body name="left/left_finger_link" pos="0.10 -0.018 0">
                    <joint name="left/left_finger" class="finger" axis="0 -1 0"/>
                    <geom name="left/left_finger_pad" type="box" size="0.012 0.006 0.028" mass="0.02" rgba="0.1 0.1 0.1 1" condim="6" friction="1 5e-3 5e-4"/>
                    <site name="left/left_finger" pos="0 0 0.028" size="0.005"/>
                  </body>
                  <body name="left/right_finger_link" pos="0.10 0.018 0">
                    <joint name="left/right_finger" class="finger" axis="0 1 0"/>
                    <geom name="left/right_finger_pad" type="box" size="0.012 0.006 0.028" mass="0.02" rgba="0.1 0.1 0.1 1" condim="6" friction="1 5e-3 5e-4"/>
                    <site name="left/right_finger" pos="0 0 0.028" size="0.005"/>
                  </body>
                  <site name="left/gripper" pos="0.12 0 0" size="0.01" rgba="0.1 0.5 1 1"/>
                </body>
              </body>
            </body>
          </body>
        </body>
      </body>
    </body>

    <body name="right/base_link" pos="0.22 -0.4 0" quat="0.70710678 0 0 0.70710678">
      <geom type="mesh" contype="0" conaffinity="0" group="1" density="0" rgba="0.75294 0.75294 0.75294 1" mesh="base_link"/>
      <geom type="mesh" rgba="0.75294 0.75294 0.75294 1" mesh="base_link"/>
      <body name="right/link1" pos="0 0 0.0603">
        <inertial pos="0.00571213 0.0002547 0.0175066" quat="0.680193 0.680193 -0.193229 0.193229" mass="0.064" diaginertia="8.61803e-05 6.38197e-05 3e-05"/>
        <joint name="right/joint1" pos="0 0 0" class="joint1"/>
        <geom type="mesh" contype="0" conaffinity="0" group="1" density="0" rgba="0.75294 0.75294 0.75294 1" mesh="link1"/>
        <geom type="mesh" rgba="0.75294 0.75294 0.75294 1" mesh="link1"/>
        <body name="right/link2" pos="0.02 0 0.0402">
          <inertial pos="-0.132257 0.00072373 4.274e-05" quat="0.00129315 0.707299 -0.000908747 0.706913" mass="1.165" diaginertia="0.0368349 0.0366996 0.000570269"/>
          <joint name="right/joint2" pos="0 0 0" class="joint2"/>
          <geom type="mesh" contype="0" conaffinity="0" group="1" density="0" rgba="0.75294 0.75294 0.75294 1" mesh="link2"/>
          <geom type="mesh" rgba="0.75294 0.75294 0.75294 1" mesh="link2"/>
          <body name="right/link3" pos="-0.264 0 0" quat="-3.67321e-06 -1 0 0">
            <inertial pos="0.190961 0.00069065 -0.0534217" quat="0.429937 0.563106 0.5511 0.440856" mass="0.546" diaginertia="0.0248663 0.0247163 0.000360764"/>
            <joint name="right/joint3" pos="0 0 0" class="joint3"/>
            <geom type="mesh" contype="0" conaffinity="0" group="1" density="0" rgba="0.75294 0.75294 0.75294 1" mesh="link3"/>
            <geom size="0.02 0.075" pos="0.15 0 -0.055" quat="0.707107 0 0.707107 0" type="cylinder" rgba="0.75294 0.75294 0.75294 1"/>
            <body name="right/link4" pos="0.245 0 -0.056">
              <inertial pos="0.0309232 0.0066107 -0.031385" quat="0.948284 -0.112586 -0.277756 0.10456" mass="0.080971" diaginertia="0.000231095 0.000214473 5.78516e-05"/>
              <joint name="right/joint4" pos="0 0 0" class="joint4"/>
              <geom type="mesh" contype="0" conaffinity="0" group="1" density="0" rgba="0.89804 0.91765 0.92941 1" mesh="link4"/>
              <geom size="0.025 0.025" pos="0.06575 -0.001 -0.02" type="cylinder" rgba="0.89804 0.91765 0.92941 1"/>
              <body name="right/link5" pos="0.06575 -0.001 -0.0825">
                <inertial pos="0.0040681 8.85e-06 0.0512068" quat="0.998879 0.000248436 0.0466541 0.00797966" mass="0.655" diaginertia="0.00256988 0.00255018 0.000249451"/>
                <joint name="right/joint5" pos="0 0 0" class="joint5"/>
                <geom type="mesh" contype="0" conaffinity="0" group="1" density="0" rgba="0.75294 0.75294 0.75294 1" mesh="link5"/>
                <geom size="0.02 0.0125" pos="0.055 0 0.083" quat="0.707107 0 0.707107 0" type="cylinder" rgba="0.75294 0.75294 0.75294 1"/>
                <body name="right/link6" pos="0.02845 0 0.0825" quat="-3.67321e-06 -1 0 0">
                  <inertial pos="0.0543717 -0.00733924 0.0188099" quat="0.391972 0.580147 0.313722 0.641378" mass="0.9021" diaginertia="0.00627428 0.00505738 0.00224351"/>
                  <joint name="right/joint6" pos="0 0 0" class="joint6"/>
                  <geom type="mesh" contype="0" conaffinity="0" group="1" density="0" rgba="0.89804 0.91765 0.92941 1" mesh="arx_gopro_finray_gripper"/>
                  <geom type="mesh" rgba="0.89804 0.91765 0.92941 1" mesh="arx_gopro_finray_gripper"/>
                  <body name="right/left_finger_link" pos="0.10 -0.018 0">
                    <joint name="right/left_finger" class="finger" axis="0 -1 0"/>
                    <geom name="right/left_finger_pad" type="box" size="0.012 0.006 0.028" mass="0.02" rgba="0.1 0.1 0.1 1" condim="6" friction="1 5e-3 5e-4"/>
                    <site name="right/left_finger" pos="0 0 0.028" size="0.005"/>
                  </body>
                  <body name="right/right_finger_link" pos="0.10 0.018 0">
                    <joint name="right/right_finger" class="finger" axis="0 1 0"/>
                    <geom name="right/right_finger_pad" type="box" size="0.012 0.006 0.028" mass="0.02" rgba="0.1 0.1 0.1 1" condim="6" friction="1 5e-3 5e-4"/>
                    <site name="right/right_finger" pos="0 0 0.028" size="0.005"/>
                  </body>
                  <site name="right/gripper" pos="0.12 0 0" size="0.01" rgba="1 0.4 0.1 1"/>
                </body>
              </body>
            </body>
          </body>
        </body>
      </body>
    </body>
  </worldbody>

  <equality>
    <joint joint1="left/left_finger" joint2="left/right_finger" polycoef="0 1 0 0 0"/>
    <joint joint1="right/left_finger" joint2="right/right_finger" polycoef="0 1 0 0 0"/>
  </equality>

  <include file="joint_position_actuators.xml"/>
</mujoco>
